Traceback (most recent call last):
  File "/usr/lib/python3/dist-packages/urllib3/connectionpool.py", line 562, in urlopen
    body=body, headers=headers)
  File "/usr/lib/python3/dist-packages/urllib3/connectionpool.py", line 387, in _make_request
    conn.request(method, url, **httplib_request_kw)
  File "/usr/lib/python3.4/http/client.py", line 1125, in request
    self._send_request(method, url, body, headers)
  File "/usr/lib/python3.4/http/client.py", line 1163, in _send_request
    self.endheaders(body)
  File "/usr/lib/python3.4/http/client.py", line 1121, in endheaders
    self._send_output(message_body)
  File "/usr/lib/python3.4/http/client.py", line 951, in _send_output
    self.send(msg)
  File "/usr/lib/python3.4/http/client.py", line 886, in send
    self.connect()
  File "/usr/lib/python3/dist-packages/urllib3/connectionpool.py", line 138, in connect
    ssl_version=resolved_ssl_version)
  File "/usr/lib/python3/dist-packages/urllib3/util.py", line 619, in ssl_wrap_socket
    return context.wrap_socket(sock, server_hostname=server_hostname)
  File "/usr/lib/python3.4/ssl.py", line 365, in wrap_socket
    _context=self)
  File "/usr/lib/python3.4/ssl.py", line 601, in __init__
    self.do_handshake()
  File "/usr/lib/python3.4/ssl.py", line 828, in do_handshake
    self._sslobj.do_handshake()
ssl.SSLError: [SSL: CERTIFICATE_VERIFY_FAILED] certificate verify failed (_ssl.c:600)

During handling of the above exception, another exception occurred:

Traceback (most recent call last):
  File "/usr/lib/python3/dist-packages/requests/adapters.py", line 330, in send
    timeout=timeout
  File "/usr/lib/python3/dist-packages/urllib3/connectionpool.py", line 595, in urlopen
    raise SSLError(e)
urllib3.exceptions.SSLError: [SSL: CERTIFICATE_VERIFY_FAILED] certificate verify failed (_ssl.c:600)

During handling of the above exception, another exception occurred:

Traceback (most recent call last):
  File "0-gather_data_from_an_API.py", line 22, in <module>
    params=payload).json()
  File "/usr/lib/python3/dist-packages/requests/api.py", line 55, in get
    return request('get', url, **kwargs)
  File "/usr/lib/python3/dist-packages/requests/api.py", line 44, in request
    return session.request(method=method, url=url, **kwargs)
  File "/usr/lib/python3/dist-packages/requests/sessions.py", line 467, in request
    resp = self.send(prep, **send_kwargs)
  File "/usr/lib/python3/dist-packages/requests/sessions.py", line 570, in send
    r = adapter.send(request, **kwargs)
  File "/usr/lib/python3/dist-packages/requests/adapters.py", line 385, in send
    raise SSLError(e)
requests.exceptions.SSLError: [SSL: CERTIFICATE_VERIFY_FAILED] certificate verify failed (_ssl.c:600)
